2024-10-24 12:59:40,598 ERROR: Exception on /explore [GET] [in /Users/anatoliykayola/python/microblog/venv/lib/python3.12/site-packages/flask/app.py:838]
Traceback (most recent call last):
  File "/Users/anatoliykayola/python/microblog/venv/lib/python3.12/site-packages/flask/app.py", line 1473, in wsgi_app
    response = self.full_dispatch_request()
               ^^^^^^^^^^^^^^^^^^^^^^^^^^^^
  File "/Users/anatoliykayola/python/microblog/venv/lib/python3.12/site-packages/flask/app.py", line 882, in full_dispatch_request
    rv = self.handle_user_exception(e)
         ^^^^^^^^^^^^^^^^^^^^^^^^^^^^^
  File "/Users/anatoliykayola/python/microblog/venv/lib/python3.12/site-packages/flask/app.py", line 880, in full_dispatch_request
    rv = self.dispatch_request()
         ^^^^^^^^^^^^^^^^^^^^^^^
  File "/Users/anatoliykayola/python/microblog/venv/lib/python3.12/site-packages/flask/app.py", line 865, in dispatch_request
    return self.ensure_sync(self.view_functions[rule.endpoint])(**view_args)  # type: ignore[no-any-return]
           ^^^^^^^^^^^^^^^^^^^^^^^^^^^^^^^^^^^^^^^^^^^^^^^^^^^^^^^^^^^^^^^^^
  File "/Users/anatoliykayola/python/microblog/venv/lib/python3.12/site-packages/flask_login/utils.py", line 290, in decorated_view
    return current_app.ensure_sync(func)(*args, **kwargs)
           ^^^^^^^^^^^^^^^^^^^^^^^^^^^^^^^^^^^^^^^^^^^^^^
  File "/Users/anatoliykayola/python/microblog/venv/microblog/app/routes.py", line 171, in explore
    posts = db.sessions.scalars(query).all()
            ^^^^^^^^^^^
  File "/Users/anatoliykayola/python/microblog/venv/lib/python3.12/site-packages/flask_sqlalchemy/extension.py", line 1008, in __getattr__
    raise AttributeError(name)
AttributeError: sessions. Did you mean: 'session'?
2024-10-24 13:00:26,161 INFO: Microblog startup [in /Users/anatoliykayola/python/microblog/venv/microblog/app/__init__.py:43]
2024-10-24 13:33:06,111 INFO: Microblog startup [in /Users/anatoliykayola/python/microblog/venv/microblog/app/__init__.py:43]
2024-10-24 13:51:11,164 INFO: Microblog startup [in /Users/anatoliykayola/python/microblog/venv/microblog/app/__init__.py:43]
2024-10-24 13:51:15,702 ERROR: Exception on /index [GET] [in /Users/anatoliykayola/python/microblog/venv/lib/python3.12/site-packages/flask/app.py:838]
Traceback (most recent call last):
  File "/Users/anatoliykayola/python/microblog/venv/lib/python3.12/site-packages/flask/app.py", line 1473, in wsgi_app
    response = self.full_dispatch_request()
               ^^^^^^^^^^^^^^^^^^^^^^^^^^^^
  File "/Users/anatoliykayola/python/microblog/venv/lib/python3.12/site-packages/flask/app.py", line 882, in full_dispatch_request
    rv = self.handle_user_exception(e)
         ^^^^^^^^^^^^^^^^^^^^^^^^^^^^^
  File "/Users/anatoliykayola/python/microblog/venv/lib/python3.12/site-packages/flask/app.py", line 880, in full_dispatch_request
    rv = self.dispatch_request()
         ^^^^^^^^^^^^^^^^^^^^^^^
  File "/Users/anatoliykayola/python/microblog/venv/lib/python3.12/site-packages/flask/app.py", line 865, in dispatch_request
    return self.ensure_sync(self.view_functions[rule.endpoint])(**view_args)  # type: ignore[no-any-return]
           ^^^^^^^^^^^^^^^^^^^^^^^^^^^^^^^^^^^^^^^^^^^^^^^^^^^^^^^^^^^^^^^^^
  File "/Users/anatoliykayola/python/microblog/venv/lib/python3.12/site-packages/flask_login/utils.py", line 290, in decorated_view
    return current_app.ensure_sync(func)(*args, **kwargs)
           ^^^^^^^^^^^^^^^^^^^^^^^^^^^^^^^^^^^^^^^^^^^^^^
  File "/Users/anatoliykayola/python/microblog/venv/microblog/app/routes.py", line 52, in index
    posts = db.session.scalars(current_user.following_posts(), page=page,
            ^^^^^^^^^^^^^^^^^^^^^^^^^^^^^^^^^^^^^^^^^^^^^^^^^^^^^^^^^^^^^
  File "/Users/anatoliykayola/python/microblog/venv/lib/python3.12/site-packages/sqlalchemy/orm/scoping.py", line 1908, in scalars
    return self._proxied.scalars(
           ^^^^^^^^^^^^^^^^^^^^^^
  File "/Users/anatoliykayola/python/microblog/venv/lib/python3.12/site-packages/sqlalchemy/orm/session.py", line 2470, in scalars
    return self._execute_internal(
           ^^^^^^^^^^^^^^^^^^^^^^^
TypeError: Session._execute_internal() got an unexpected keyword argument 'page'
2024-10-24 13:53:57,426 INFO: Microblog startup [in /Users/anatoliykayola/python/microblog/venv/microblog/app/__init__.py:43]
2024-10-24 13:54:00,087 ERROR: Exception on /index [GET] [in /Users/anatoliykayola/python/microblog/venv/lib/python3.12/site-packages/flask/app.py:838]
Traceback (most recent call last):
  File "/Users/anatoliykayola/python/microblog/venv/lib/python3.12/site-packages/flask/app.py", line 1473, in wsgi_app
    response = self.full_dispatch_request()
               ^^^^^^^^^^^^^^^^^^^^^^^^^^^^
  File "/Users/anatoliykayola/python/microblog/venv/lib/python3.12/site-packages/flask/app.py", line 882, in full_dispatch_request
    rv = self.handle_user_exception(e)
         ^^^^^^^^^^^^^^^^^^^^^^^^^^^^^
  File "/Users/anatoliykayola/python/microblog/venv/lib/python3.12/site-packages/flask/app.py", line 880, in full_dispatch_request
    rv = self.dispatch_request()
         ^^^^^^^^^^^^^^^^^^^^^^^
  File "/Users/anatoliykayola/python/microblog/venv/lib/python3.12/site-packages/flask/app.py", line 865, in dispatch_request
    return self.ensure_sync(self.view_functions[rule.endpoint])(**view_args)  # type: ignore[no-any-return]
           ^^^^^^^^^^^^^^^^^^^^^^^^^^^^^^^^^^^^^^^^^^^^^^^^^^^^^^^^^^^^^^^^^
  File "/Users/anatoliykayola/python/microblog/venv/lib/python3.12/site-packages/flask_login/utils.py", line 290, in decorated_view
    return current_app.ensure_sync(func)(*args, **kwargs)
           ^^^^^^^^^^^^^^^^^^^^^^^^^^^^^^^^^^^^^^^^^^^^^^
  File "/Users/anatoliykayola/python/microblog/venv/microblog/app/routes.py", line 52, in index
    posts = db.session.scalars(current_user.following_posts(), page=page,
           ^^^^^^^^^^^^^^^^^^^^^^^^^^^^^^^^^^^^^^^^^^^^^^^^^^^^^^^^^^^^^^
  File "/Users/anatoliykayola/python/microblog/venv/lib/python3.12/site-packages/sqlalchemy/orm/scoping.py", line 1908, in scalars
    return self._proxied.scalars(
           ^^^^^^^^^^^^^^^^^^^^^^
  File "/Users/anatoliykayola/python/microblog/venv/lib/python3.12/site-packages/sqlalchemy/orm/session.py", line 2470, in scalars
    return self._execute_internal(
           ^^^^^^^^^^^^^^^^^^^^^^^
TypeError: Session._execute_internal() got an unexpected keyword argument 'page'
2024-10-24 13:54:11,416 ERROR: Exception on /index [GET] [in /Users/anatoliykayola/python/microblog/venv/lib/python3.12/site-packages/flask/app.py:838]
Traceback (most recent call last):
  File "/Users/anatoliykayola/python/microblog/venv/lib/python3.12/site-packages/flask/app.py", line 1473, in wsgi_app
    response = self.full_dispatch_request()
               ^^^^^^^^^^^^^^^^^^^^^^^^^^^^
  File "/Users/anatoliykayola/python/microblog/venv/lib/python3.12/site-packages/flask/app.py", line 882, in full_dispatch_request
    rv = self.handle_user_exception(e)
         ^^^^^^^^^^^^^^^^^^^^^^^^^^^^^
  File "/Users/anatoliykayola/python/microblog/venv/lib/python3.12/site-packages/flask/app.py", line 880, in full_dispatch_request
    rv = self.dispatch_request()
         ^^^^^^^^^^^^^^^^^^^^^^^
  File "/Users/anatoliykayola/python/microblog/venv/lib/python3.12/site-packages/flask/app.py", line 865, in dispatch_request
    return self.ensure_sync(self.view_functions[rule.endpoint])(**view_args)  # type: ignore[no-any-return]
           ^^^^^^^^^^^^^^^^^^^^^^^^^^^^^^^^^^^^^^^^^^^^^^^^^^^^^^^^^^^^^^^^^
  File "/Users/anatoliykayola/python/microblog/venv/lib/python3.12/site-packages/flask_login/utils.py", line 290, in decorated_view
    return current_app.ensure_sync(func)(*args, **kwargs)
           ^^^^^^^^^^^^^^^^^^^^^^^^^^^^^^^^^^^^^^^^^^^^^^
  File "/Users/anatoliykayola/python/microblog/venv/microblog/app/routes.py", line 52, in index
    posts = db.session.scalars(current_user.following_posts(), page=page,
           ^^^^^^^^^^^^^^^^^^^^^^^^^^^^^^^^^^^^^^^^^^^^^^^^^^^^^^^^^^^^^^
  File "/Users/anatoliykayola/python/microblog/venv/lib/python3.12/site-packages/sqlalchemy/orm/scoping.py", line 1908, in scalars
    return self._proxied.scalars(
           ^^^^^^^^^^^^^^^^^^^^^^
  File "/Users/anatoliykayola/python/microblog/venv/lib/python3.12/site-packages/sqlalchemy/orm/session.py", line 2470, in scalars
    return self._execute_internal(
           ^^^^^^^^^^^^^^^^^^^^^^^
TypeError: Session._execute_internal() got an unexpected keyword argument 'page'
2024-10-24 14:30:39,963 INFO: Microblog startup [in /Users/anatoliykayola/python/microblog/venv/microblog/app/__init__.py:43]
